Workbook

Sheet Descriptive Analysis
A1: SBP_Change | C1: Adherence_pct2 | E1: Age | G1: BMI | I1: FBS
A3: Mean | B3: 10.11 | C3: Mean | D3: 82.186 | E3: Mean | F3: 51.96 | G3: Mean | H3: 28.009836 | I3: Mean | J3: 108.404
A4: Standard Error | B4: 0.39311178 | C4: Standard Error | D4: 0.59502177 | E4: Standard Error | F4: 0.55139539 | G4: Standard Error | H4: 0.22315243 | I4: Standard Error | J4: 0.76223065
A5: Median | B5: 11 | C5: Median | D5: 82 | E5: Median | F5: 52 | G5: Median | H5: 28.009836 | I5: Median | J5: 109.5
A6: Mode | B6: 14 | C6: Mode | D6: 100 | E6: Mode | F6: 58 | G6: Mode | H6: 28.009836 | I6: Mode | J6: 137
A7: Standard Deviation | B7: 8.7902467 | C7: Standard Deviation | D7: 13.305091 | E7: Standard Deviation | F7: 12.329576 | G7: Standard Deviation | H7: 4.9898399 | I7: Standard Deviation | J7: 17.043995
A8: Sample Variance | B8: 77.268437 | C8: Sample Variance | D8: 177.02545 | E8: Sample Variance | F8: 152.01844 | G8: Sample Variance | H8: 24.898503 | I8: Sample Variance | J8: 290.49778
A9: Kurtosis | B9: -0.32391271 | C9: Kurtosis | D9: -0.499103 | E9: Kurtosis | F9: -0.12196287 | G9: Kurtosis | H9: -0.14281914 | I9: Kurtosis | J9: -0.056529956
A10: Skewness | B10: -0.12256282 | C10: Skewness | D10: -0.38793129 | E10: Skewness | F10: 0.052376264 | G10: Skewness | H10: -0.046570831 | I10: Skewness | J10: -0.15101854
A11: Range | B11: 49 | C11: Range | D11: 60 | E11: Range | F11: 65 | G11: Range | H11: 26.3 | I11: Range | J11: 105
A12: Minimum | B12: -14 | C12: Minimum | D12: 40 | E12: Minimum | F12: 20 | G12: Minimum | H12: 16 | I12: Minimum | J12: 54
A13: Maximum | B13: 35 | C13: Maximum | D13: 100 | E13: Maximum | F13: 85 | G13: Maximum | H13: 42.3 | I13: Maximum | J13: 159
A14: Sum | B14: 5055 | C14: Sum | D14: 41093 | E14: Sum | F14: 25980 | G14: Sum | H14: 14004.918 | I14: Sum | J14: 54202
... A18: Confidence Level(95.0%) | B18: 0.77235827 | C18: Confidence Level(95.0%) | D18: 1.1690568 | E18: Confidence Level(95.0%) | F18: 1.0833427 | G18: Confidence Level(95.0%) | H18: 0.43843413 | I18: Confidence Level(95.0%) | J18: 1.497577

Sheet Summary Analysis
A3: Gender | B3: Count of Sex | C3: Percentage of Sex2 | D3: Average of Age_Years | E3: Gender | F3: Average of BMI | I3: Zone | J3: Count of Zone | K3: Percentage of Zone | N3: Family history of HTN | O3: Count of Family_History_HTN | P3: Percentage of Family_History_HTN
A4: Female | B4: 267 | C4: 0.534 | D4: 51.96 | E4: Female | F4: 28.235912 | I4: North Central | J4: 72 | K4: 0.144 | N4: No | O4: 304 | P4: 0.608
A5: Male | B5: 233 | C5: 0.466 | E5: Male | F5: 27.75077 | I5: North East | J5: 87 | K5: 0.174 | N5: Yes | O5: 196 | P5: 0.392
A6: Grand Total | B6: 500 | C6: 1 | E6: Grand Total | F6: 28.009836 | I6: North West | J6: 83 | K6: 0.166 | N6: Grand Total | O6: 500 | P6: 1
I7: South East | J7: 95 | K7: 0.19
I8: South South | J8: 85 | K8: 0.17
I9: South West | J9: 78 | K9: 0.156 | N9: Average of Fasting_Glucose_mgdL | P9: Treatment_Group | Q9: Count of Treatment_Group | R9: Percentage of Treatment_Group
I10: Grand Total | J10: 500 | K10: 1 | N10: 108.404 | P10: Drug A | Q10: 168 | R10: 0.336
A11: Average of BMI | C11: Smoking Activities | D11: Count of Smoking_Status2 | E11: Percentage of Smoking_Status | P11: Drug B | Q11: 160 | R11: 0.32
A12: 28.009836 | C12: Current | D12: 96 | E12: 0.192 | P12: Placebo | Q12: 172 | R12: 0.344
C13: Former | D13: 96 | E13: 0.192 | P13: Grand Total | Q13: 500 | R13: 1
C14: Never | D14: 308 | E14: 0.616 | I14: Physical activities | J14: Count of Physical_Activity | K14: Percentage of Physical_Activity
C15: Grand Total | D15: 500 | E15: 1 | I15: High | J15: 98 | K15: 0.196 | N15: Row Labels | O15: Count of Adverse_Event | P15: Percentage of Adverse_Event
I16: Low | J16: 208 | K16: 0.416 | N16: No | O16: 410 | P16: 0.82
I17: Moderate | J17: 194 | K17: 0.388 | N17: Yes | O17: 90 | P17: 0.18
I18: Grand Total | J18: 500 | K18: 1 | N18: Grand Total | O18: 500 | P18: 1
A19: t-Test: Paired Two Sample for Means
B21: Baseline_SBP | C21: Week_12_SBP | E21: SBP_CHANGE | I21: SBP_Change | J21: Adherence Percentage
A22: Mean | B22: 128.412 | C22: 118.302 | H22: SBP_Change | I22: 1 | M22: Row Labels | N22: Average of SBP_Change | O22: Percentage of SBP_Change
A23: Variance | B23: 145.9742 | C23: 195.26933 | E23: Mean | F23: 10.11 | H23: Adherence Percentage | I23: 0.11250354 | J23: 1 | M23: Drug A | N23: 10.642857 | O23: 0.3537092
A24: Observations | B24: 500 | C24: 500 | E24: Standard Error | F24: 0.39311178 | M24: Drug B | N24: 16.11875 | O24: 0.51018793
A25: Pearson Correlation | B25: 0.781768 | E25: Median | F25: 11 | M25: Placebo | N25: 4 | O25: 0.13610287
A26: Hypothesized Mean Difference | B26: 0 | E26: Mode | F26: 14 | M26: Grand Total | N26: 10.11 | O26: 1
A27: df | B27: 499 | E27: Standard Deviation | F27: 8.7902467
A28: t Stat | B28: 25.717876 | E28: Sample Variance | F28: 77.268437 | Q28: Anova: Single Factor
A29: P(T<=t) one-tail | B29: 8.4853169e-94 | E29: Kurtosis | F29: -0.32391271
A30: t Critical one-tail | B30: 1.647913 | E30: Skewness | F30: -0.12256282 | Q30: SUMMARY
A31: P(T<=t) two-tail | B31: 1.6970634e-93 | E31: Range | F31: 49 | Q31: Groups | R31: Count | S31: Sum | T31: Average | U31: Variance
A32: t Critical two-tail | B32: 1.9647294 | E32: Minimum | F32: -14 | Q32: Drug A | R32: 168 | S32: 1788 | T32: 10.642857 | U32: 57.823781
E33: Maximum | F33: 35 | Q33: Drug B | R33: 160 | S33: 2579 | T33: 16.11875 | U33: 44.872602
E34: Sum | F34: 5055 | Q34: Placebo | R34: 172 | S34: 688 | T34: 4 | U34: 55.672515
E35: Count | F35: 500
E36: Confidence Level(95.0%) | F36: 0.77235827
Q37: ANOVA
G38: Percentage of Adverse_Event | H38: Column Labels | Q38: Source of Variation | R38: SS | S38: df | T38: MS | U38: F | V38: P-value | W38: F crit
G39: Row Labels | H39: Yes | Q39: Between Groups | R39: 12245.635 | S39: 2 | T39: 6122.8174 | U39: 115.65519 | V39: 5.7399928e-42 | W39: 3.0138622
G40: Drug A | H40: 30 | Q40: Within Groups | R40: 26311.315 | S40: 497 | T40: 52.940272
G41: Drug B | H41: 48
G42: Placebo | H42: 12 | Q42: Total | R42: 38556.95 | S42: 499
A43: Correlation
...

Sheet Observed&Expected
A1: Observed Table | B1: Placebo | C1: Drug A | D1: Drug B | E1: Total | I1: Drug A | J1: Drug B | K1: Placebo | M1: Attribute | N1: Value
A2: Yes | B2: =COUNTIFS(Data!$T$2:$T$501,'Observed&Expected'!$A2,Data!$P$2:$P$501,'Observed&Expected'!B$1) -> 12 | C2: =COUNTIFS(Data!$T$2:$T$501,'Observed&Expected'!$A2,Data!$P$2:$P$501,'Observed&Expected'!C$1) -> 30 | D2: =COUNTIFS(Data!$T$2:$T$501,'Observed&Expected'!$A2,Data!$P$2:$P$501,'Observed&Expected'!D$1) -> 48 | E2: =SUM(B2:D2) -> 90 | I2: 15 | J2: 8 | K2: 3 | M2: Drug A | N2: 15
A3: No | B3: =COUNTIFS(Data!$T$2:$T$501,'Observed&Expected'!$A3,Data!$P$2:$P$501,'Observed&Expected'!B$1) -> 160 | C3: =COUNTIFS(Data!$T$2:$T$501,'Observed&Expected'!$A3,Data!$P$2:$P$501,'Observed&Expected'!C$1) -> 138 | D3: =COUNTIFS(Data!$T$2:$T$501,'Observed&Expected'!$A3,Data!$P$2:$P$501,'Observed&Expected'!D$1) -> 112 | E3: =SUM(B3:D3) -> 410 | I3: 9 | J3: 17 | K3: -3 | M3: Drug B | N3: 8
A4: Total | B4: =SUM(B2:B3) -> 172 | C4: =SUM(C2:C3) -> 168 | D4: =SUM(D2:D3) -> 160 | E4: =SUM(B4:D4) -> 500 | I4: 9 | J4: 12 | K4: 5 | M4: Placebo | N4: 3
I5: 11 | J5: 7 | K5: 7 | M5: Drug A | N5: 9
A6: Expected Table | B6: Placebo | C6: Drug A | D6: Drug B | E6: Total | I6: 9 | J6: 8 | K6: 1 | M6: Drug B | N6: 17
A7: Yes | B7: =$E2*B$4/$E$4 -> 30.96 | C7: =$E2*C$4/$E$4 -> 30.24 | D7: =$E2*D$4/$E$4 -> 28.8 | E7: =SUM(B7:D7) -> 90 | I7: 17 | J7: 11 | K7: 5 | M7: Placebo | N7: -3
A8: No | B8: =$E3*B$4/$E$4 -> 141.04 | C8: =$E3*C$4/$E$4 -> 137.76 | D8: =$E3*D$4/$E$4 -> 131.2 | E8: =SUM(B8:D8) -> 410 | I8: 25 | J8: 27 | K8: 2 | M8: Drug A | N8: 9
A9: Total | B9: =SUM(B7:B8) -> 172 | C9: =SUM(C7:C8) -> 168 | D9: =SUM(D7:D8) -> 160 | E9: =SUM(B9:D9) -> 500 | I9: 12 | J9: 11 | K9: 1 | M9: Drug B | N9: 12
I10: 17 | J10: 15 | K10: 2 | M10: Placebo | N10: 5
A11: p-value | B11: =_xlfn.CHISQ.TEST(B2:D3,B7:D8) -> 3.4283492e-07 | I11: 13 | J11: -2 | K11: 15 | M11: Drug A | N11: 11
A12: Chi-square value | B12: {=SUMPRODUCT((B2:D3-B7:D8)^2/B7:D8)} -> 29.772034 | I12: -1 | J12: 8 | K12: 3 | M12: Drug B | N12: 7
I13: 4 | J13: 12 | K13: 3 | M13: Placebo | N13: 7
I14: 11 | J14: 23 | K14: -5 | M14: Drug A | N14: 9
I15: 16 | J15: 19 | K15: 6 | M15: Drug B | N15: 8
I16: 16 | J16: 16 | K16: 0 | M16: Placebo | N16: 1
I17: 19 | J17: 21 | K17: -2 | M17: Drug A | N17: 17
I18: 6 | J18: 16 | K18: 1 | M18: Drug B | N18: 11
I19: -6 | J19: 14 | K19: -4 | M19: Placebo | N19: 5
I20: 1 | J20: 28 | K20: 6 | M20: Drug A | N20: 25
I21: 9 | J21: 17 | K21: 7 | M21: Drug B | N21: 27
I22: 15 | J22: 8 | K22: 0 | M22: Placebo | N22: 2
I23: 8 | J23: -2 | K23: 16 | M23: Drug A | N23: 12
I24: 16 | J24: 13 | K24: 13 | M24: Drug B | N24: 11
... I161: 14 | J161: 4 | K161: 6 | M161: Drug A | N161: 2
I162: 1 | K162: 3 | M162: Drug B | N162: 15
I163: 21 | K163: 10 | M163: Placebo | N163: 12
I164: 10 | K164: 4 | M164: Drug A | N164: 12
I165: 10 | K165: 8 | M165: Drug B | N165: 19
I166: 11 | K166: 1 | M166: Placebo | N166: 4
I167: 13 | K167: 12 | M167: Drug A | N167: 8
I168: 17 | K168: -3 | M168: Drug B | N168: 25
I169: 10 | K169: -7 | M169: Placebo | N169: 20
K170: 8 | M170: Drug A | N170: 9
K171: 17 | M171: Drug B | N171: 8
K172: 7 | M172: Placebo | N172: 10
K173: -5 | M173: Drug A | N173: 10
M174: Drug B | N174: 21
M175: Placebo | N175: -9
M176: Drug A | N176: 15
...

Sheet Regression Statistics
A1: SUMMARY OUTPUT
A3: Regression Statistics
A4: Multiple R | B4: 0.58282233
A5: R Square | B5: 0.33968187
A6: Adjusted R Square | B6: 0.32479765
A7: Standard Error | B7: 7.223007
A8: Observations | B8: 500
A10: ANOVA
B11: df | C11: SS | D11: MS | E11: F | F11: Significance F
A12: Regression | B12: 11 | C12: 13097.097 | D12: 1190.6452 | E12: 22.82161 | F12: 9.3657871e-38
A13: Residual | B13: 488 | C13: 25459.853 | D13: 52.17183
A14: Total | B14: 499 | C14: 38556.95
B16: Coefficients | C16: Standard Error | D16: t Stat | E16: P-value | F16: Lower 95% | G16: Upper 95% | H16: Lower 95.0% | I16: Upper 95.0%
A17: Constant | B17: -0.82295879 | C17: 4.0824914 | D17: -0.20158249 | E17: 0.84032713 | F17: -8.8443892 | G17: 7.1984716 | H17: -8.8443892 | I17: 7.1984716
A18: Adherence_pct2 | B18: 0.051095471 | C18: 0.02449704 | D18: 2.0857814 | E18: 0.037517282 | F18: 0.002962778 | G18: 0.099228165 | H18: 0.002962778 | I18: 0.099228165
A19: Age | B19: -0.0036436758 | C19: 0.026382284 | D19: -0.1381107 | E19: 0.8902099 | F19: -0.055480566 | G19: 0.048193214 | H19: -0.055480566 | I19: 0.048193214
A20: BMI2 | B20: 0.025119444 | C20: 0.072235275 | D20: 0.34774484 | E20: 0.72818176 | F20: -0.1168111 | G20: 0.16704999 | H20: -0.1168111 | I20: 0.16704999
A21: Fasting_Blood_Glucose | B21: -0.011271727 | C21: 0.027906431 | D21: -0.40391145 | E21: 0.68645478 | F21: -0.066103316 | G21: 0.043559863 | H21: -0.066103316 | I21: 0.043559863
A22: Drug_A | B22: 6.6351218 | C22: 0.79267318 | D22: 8.3705643 | E22: 6.0984641e-16 | F22: 5.0776481 | G22: 8.1925954 | H22: 5.0776481 | I22: 8.1925954
A23: Drug_B | B23: 12.162491 | C23: 0.80229545 | D23: 15.159617 | E23: 8.1375477e-43 | F23: 10.586112 | G23: 13.738871 | H23: 10.586112 | I23: 13.738871
A24: Current_Smoker | B24: 2.3722936 | C24: 0.84977937 | D24: 2.7916583 | E24: 0.005449535 | F24: 0.70261563 | G24: 4.0419716 | H24: 0.70261563 | I24: 4.0419716
A25: Former_Smoker | B25: 0.4991647 | C25: 0.84829827 | D25: 0.58843065 | E25: 0.55651551 | F25: -1.1676032 | G25: 2.1659326 | H25: -1.1676032 | I25: 2.1659326
A26: Moderate_Activity | B26: 1.2792036 | C26: 0.73780227 | D26: 1.7338028 | E26: 0.083584644 | F26: -0.1704576 | G26: 2.7288649 | H26: -0.1704576 | I26: 2.7288649
A27: High_Activity | B27: 0.10657089 | C27: 0.88981694 | D27: 0.11976721 | E27: 0.90471685 | F27: -1.6417744 | G27: 1.8549162 | H27: -1.6417744 | I27: 1.8549162
A28: HbA1c | B28: 0.048076261 | C28: 0.78668652 | D28: 0.061112349 | E28: 0.95129475 | F28: -1.4976346 | G28: 1.5937871 | H28: -1.4976346 | I28: 1.5937871

Sheet Data
A1: Patient_ID | B1: Enrolment_Date | C1: Age_Years | D1: Age_Range | E1: Sex | F1: Zone | G1: BMI | H1: Smoking_Status | I1: Physical_Activity | J1: Family_History_HTN | K1: Baseline_SBP | L1: Baseline_DBP | M1: Fasting_Glucose_mgdL | N1: HbA1c_pct | O1: Total_Cholesterol_mgdL | P1: Treatment_Group | Q1: Adherence_pct | R1: Week12_SBP | S1: Week12_DBP | T1: Adverse_Event | U1: SBP_Change | V1: Adherence_pct2 | W1: Age | X1: BMI2 | Y1: Fasting_Blood_Glucose | Z1: Drug_A | AA1: Drug_B | AB1: Current_Smoker | AC1: Former_Smoker | AD1: Moderate_Activity | AE1: High_Activity | AF1: HbA1c
A2: P1000 | B2: 45699 | C2: 56 | D2: {=_xlfn.IFS(Table1[[#This Row],[Age_Years]]<29, "20 - 29", Table1[[#This Row],[Age_Years]]<39, "30 - 39", Table1[[#This Row],[Age_Years]] <49, "40 - 49", Table1[[#This Row],[Age_Years]]<59, "50 - 59",Table1[[#This Row],[Age_Years]]<69, "60 - 69",Table1[[#This Row],[Age_Years]]<79, "70 - 79", Table1[[#This Row],[Age_Years]]<89, "80 - 89", TRUE, "90+")} -> 50 - 59 | E2: Male | F2: South West | G2: 26 | H2: Never | I2: Moderate | J2: Yes | K2: 141 | L2: 82 | M2: 136 | N2: 6.2 | O2: 167 | P2: Placebo | Q2: 70 | R2: 138 | S2: 84 | T2: No | U2: =Table1[[#This Row],[Baseline_SBP]]-Table1[[#This Row],[Week12_SBP]] -> 3 | V2: 70 | W2: 56 | X2: 26 | Y2: 136 | Z2: =IF(P2="Drug A", 1,0) -> 0 | AA2: =IF(P2="Drug B", 1,0) -> 0 | AB2: =IF(H2="Current",1,0) -> 0 | AC2: =IF(H2="Former",1,0) -> 0 | AD2: =IF(I2="Moderate",1,0) -> 1 | AE2: =IF(I2="High",1,0) -> 0 | AF2: =N2 -> 6.2
A3: P1001 | B3: 45839 | C3: 38 | D3: {=_xlfn.IFS(Table1[[#This Row],[Age_Years]]<29, "20 - 29", Table1[[#This Row],[Age_Years]]<39, "30 - 39", Table1[[#This Row],[Age_Years]] <49, "40 - 49", Table1[[#This Row],[Age_Years]]<59, "50 - 59",Table1[[#This Row],[Age_Years]]<69, "60 - 69",Table1[[#This Row],[Age_Years]]<79, "70 - 79", Table1[[#This Row],[Age_Years]]<89, "80 - 89", TRUE, "90+")} -> 30 - 39 | E3: Male | F3: South South | G3: 25.1 | H3: Never | I3: Moderate | J3: Yes | K3: 126 | L3: 80 | M3: 118 | N3: 5.8 | O3: 139 | P3: Drug A | Q3: 97 | R3: 111 | S3: 81 | T3: No | U3: =Table1[[#This Row],[Baseline_SBP]]-Table1[[#This Row],[Week12_SBP]] -> 15 | V3: 97 | W3: 38 | X3: 25.1 | Y3: 118 | Z3: =IF(P3="Drug A", 1,0) -> 1 | AA3: =IF(P3="Drug B", 1,0) -> 0 | AB3: =IF(H3="Current",1,0) -> 0 | AC3: =IF(H3="Former",1,0) -> 0 | AD3: =IF(I3="Moderate",1,0) -> 1 | AE3: =IF(I3="High",1,0) -> 0 | AF3: =N3 -> 5.8
A4: P1002 | B4: 45673 | C4: 62 | D4: {=_xlfn.IFS(Table1[[#This Row],[Age_Years]]<29, "20 - 29", Table1[[#This Row],[Age_Years]]<39, "30 - 39", Table1[[#This Row],[Age_Years]] <49, "40 - 49", Table1[[#This Row],[Age_Years]]<59, "50 - 59",Table1[[#This Row],[Age_Years]]<69, "60 - 69",Table1[[#This Row],[Age_Years]]<79, "70 - 79", Table1[[#This Row],[Age_Years]]<89, "80 - 89", TRUE, "90+")} -> 60 - 69 | E4: Female | F4: North East | G4: 32.7 | H4: Never | I4: Low | J4: Yes | K4: 137 | L4: 82 | M4: 114 | N4: 5.7 | O4: 205 | P4: Drug B | Q4: 100 | R4: 129 | S4: 77 | T4: No | U4: =Table1[[#This Row],[Baseline_SBP]]-Table1[[#This Row],[Week12_SBP]] -> 8 | V4: 100 | W4: 62 | X4: 32.7 | Y4: 114 | Z4: =IF(P4="Drug A", 1,0) -> 0 | AA4: =IF(P4="Drug B", 1,0) -> 1 | AB4: =IF(H4="Current",1,0) -> 0 | AC4: =IF(H4="Former",1,0) -> 0 | AD4: =IF(I4="Moderate",1,0) -> 0 | AE4: =IF(I4="High",1,0) -> 0 | AF4: =N4 -> 5.7
A5: P1003 | B5: 45670 | C5: 56 | D5: {=_xlfn.IFS(Table1[[#This Row],[Age_Years]]<29, "20 - 29", Table1[[#This Row],[Age_Years]]<39, "30 - 39", Table1[[#This Row],[Age_Years]] <49, "40 - 49", Table1[[#This Row],[Age_Years]]<59, "50 - 59",Table1[[#This Row],[Age_Years]]<69, "60 - 69",Table1[[#This Row],[Age_Years]]<79, "70 - 79", Table1[[#This Row],[Age_Years]]<89, "80 - 89", TRUE, "90+")} -> 50 - 59 | E5: Male | F5: South East | G5: 34.9 | H5: Never | I5: Moderate | J5: Yes | K5: 147 | L5: 88 | M5: 121 | N5: 5.8 | O5: 179 | P5: Placebo | Q5: 50 | R5: 150 | S5: 95 | T5: No | U5: =Table1[[#This Row],[Baseline_SBP]]-Table1[[#This Row],[Week12_SBP]] -> -3 | V5: 50 | W5: 56 | X5: 34.9 | Y5: 121 | Z5: =IF(P5="Drug A", 1,0) -> 0 | AA5: =IF(P5="Drug B", 1,0) -> 0 | AB5: =IF(H5="Current",1,0) -> 0 | AC5: =IF(H5="Former",1,0) -> 0 | AD5: =IF(I5="Moderate",1,0) -> 1 | AE5: =IF(I5="High",1,0) -> 0 | AF5: =N5 -> 5.8
A6: P1004 | B6: 45786 | C6: 38 | D6: {=_xlfn.IFS(Table1[[#This Row],[Age_Years]]<29, "20 - 29", Table1[[#This Row],[Age_Years]]<39, "30 - 39", Table1[[#This Row],[Age_Years]] <49, "40 - 49", Table1[[#This Row],[Age_Years]]<59, "50 - 59",Table1[[#This Row],[Age_Years]]<69, "60 - 69",Table1[[#This Row],[Age_Years]]<79, "70 - 79", Table1[[#This Row],[Age_Years]]<89, "80 - 89", TRUE, "90+")} -> 30 - 39 | E6: Male | F6: South East | G6: 36.5 | H6: Never | I6: Low | J6: No | K6: 125 | L6: 80 | M6: 123 | N6: 5.6 | O6: 164 | P6: Drug A | Q6: 92 | R6: 116 | S6: 83 | T6: Yes | U6: =Table1[[#This Row],[Baseline_SBP]]-Table1[[#This Row],[Week12_SBP]] -> 9 | V6: 92 | W6: 38 | X6: 36.5 | Y6: 123 | Z6: =IF(P6="Drug A", 1,0) -> 1 | AA6: =IF(P6="Drug B", 1,0) -> 0 | AB6: =IF(H6="Current",1,0) -> 0 | AC6: =IF(H6="Former",1,0) -> 0 | AD6: =IF(I6="Moderate",1,0) -> 0 | AE6: =IF(I6="High",1,0) -> 0 | AF6: =N6 -> 5.6
A7: P1005 | B7: 45871 | C7: 62 | D7: {=_xlfn.IFS(Table1[[#This Row],[Age_Years]]<29, "20 - 29", Table1[[#This Row],[Age_Years]]<39, "30 - 39", Table1[[#This Row],[Age_Years]] <49, "40 - 49", Table1[[#This Row],[Age_Years]]<59, "50 - 59",Table1[[#This Row],[Age_Years]]<69, "60 - 69",Table1[[#This Row],[Age_Years]]<79, "70 - 79", Table1[[#This Row],[Age_Years]]<89, "80 - 89", TRUE, "90+")} -> 60 - 69 | E7: male | F7: South East | G7: 34.9 | H7: Former | I7: Moderate | J7: No | K7: 134 | L7: 81 | M7: 137 | N7: 5.5 | O7: 183 | P7: Placebo | Q7: 57 | R7: 129 | S7: 84 | T7: No | U7: =Table1[[#This Row],[Baseline_SBP]]-Table1[[#This Row],[Week12_SBP]] -> 5 | V7: 57 | W7: 62 | X7: 34.9 | Y7: 137 | Z7: =IF(P7="Drug A", 1,0) -> 0 | AA7: =IF(P7="Drug B", 1,0) -> 0 | AB7: =IF(H7="Current",1,0) -> 0 | AC7: =IF(H7="Former",1,0) -> 1 | AD7: =IF(I7="Moderate",1,0) -> 1 | AE7: =IF(I7="High",1,0) -> 0 | AF7: =N7 -> 5.5
A8: P1006 | B8: 45695 | C8: 64 | D8: {=_xlfn.IFS(Table1[[#This Row],[Age_Years]]<29, "20 - 29", Table1[[#This Row],[Age_Years]]<39, "30 - 39", Table1[[#This Row],[Age_Years]] <49, "40 - 49", Table1[[#This Row],[Age_Years]]<59, "50 - 59",Table1[[#This Row],[Age_Years]]<69, "60 - 69",Table1[[#This Row],[Age_Years]]<79, "70 - 79", Table1[[#This Row],[Age_Years]]<89, "80 - 89", TRUE, "90+")} -> 60 - 69 | E8: Female | F8: South East | G8: 27.8 | H8: Never | I8: Low | J8: Yes | K8: 127 | L8: 76 | M8: 103 | N8: 5.3 | O8: 164 | P8: Drug A | Q8: 88 | R8: 118 | S8: 74 | T8: No | U8: =Table1[[#This Row],[Baseline_SBP]]-Table1[[#This Row],[Week12_SBP]] -> 9 | V8: 88 | W8: 64 | X8: 27.8 | Y8: 103 | Z8: =IF(P8="Drug A", 1,0) -> 1 | AA8: =IF(P8="Drug B", 1,0) -> 0 | AB8: =IF(H8="Current",1,0) -> 0 | AC8: =IF(H8="Former",1,0) -> 0 | AD8: =IF(I8="Moderate",1,0) -> 0 | AE8: =IF(I8="High",1,0) -> 0 | AF8: =N8 -> 5.3
A9: P1007 | B9: 45811 | C9: 27 | D9: {=_xlfn.IFS(Table1[[#This Row],[Age_Years]]<29, "20 - 29", Table1[[#This Row],[Age_Years]]<39, "30 - 39", Table1[[#This Row],[Age_Years]] <49, "40 - 49", Table1[[#This Row],[Age_Years]]<59, "50 - 59",Table1[[#This Row],[Age_Years]]<69, "60 - 69",Table1[[#This Row],[Age_Years]]<79, "70 - 79", Table1[[#This Row],[Age_Years]]<89, "80 - 89", TRUE, "90+")} -> 20 - 29 | E9: Female | F9: South East | G9: 30.1 | H9: Never | I9: Moderate | J9: No | K9: 127 | L9: 80 | M9: 109 | N9: 5.5 | O9: 206 | P9: Drug A | Q9: 79 | R9: 116 | S9: 73 | T9: No | U9: =Table1[[#This Row],[Baseline_SBP]]-Table1[[#This Row],[Week12_SBP]] -> 11 | V9: 79 | W9: 27 | X9: 30.1 | Y9: 109 | Z9: =IF(P9="Drug A", 1,0) -> 1 | AA9: =IF(P9="Drug B", 1,0) -> 0 | AB9: =IF(H9="Current",1,0) -> 0 | AC9: =IF(H9="Former",1,0) -> 0 | AD9: =IF(I9="Moderate",1,0) -> 1 | AE9: =IF(I9="High",1,0) -> 0 | AF9: =N9 -> 5.5
A10: P1008 | B10: 45906 | C10: 35 | D10: {=_xlfn.IFS(Table1[[#This Row],[Age_Years]]<29, "20 - 29", Table1[[#This Row],[Age_Years]]<39, "30 - 39", Table1[[#This Row],[Age_Years]] <49, "40 - 49", Table1[[#This Row],[Age_Years]]<59, "50 - 59",Table1[[#This Row],[Age_Years]]<69, "60 - 69",Table1[[#This Row],[Age_Years]]<79, "70 - 79", Table1[[#This Row],[Age_Years]]<89, "80 - 89", TRUE, "90+")} -> 30 - 39 | E10: Male | F10: South East | G10: 31.3 | H10: Former | I10: High | J10: No | K10: 126 | L10: 81 | M10: 116 | N10: 5.3 | O10: 220 | P10: Placebo | Q10: 84 | R10: 119 | S10: 79 | T10: No | U10: =Table1[[#This Row],[Baseline_SBP]]-Table1[[#This Row],[Week12_SBP]] -> 7 | V10: 84 | W10: 35 | X10: 31.3 | Y10: 116 | Z10: =IF(P10="Drug A", 1,0) -> 0 | AA10: =IF(P10="Drug B", 1,0) -> 0 | AB10: =IF(H10="Current",1,0) -> 0 | AC10: =IF(H10="Former",1,0) -> 1 | AD10: =IF(I10="Moderate",1,0) -> 0 | AE10: =IF(I10="High",1,0) -> 1 | AF10: =N10 -> 5.3
A11: P1009 | B11: 45850 | C11: 54 | D11: {=_xlfn.IFS(Table1[[#This Row],[Age_Years]]<29, "20 - 29", Table1[[#This Row],[Age_Years]]<39, "30 - 39", Table1[[#This Row],[Age_Years]] <49, "40 - 49", Table1[[#This Row],[Age_Years]]<59, "50 - 59",Table1[[#This Row],[Age_Years]]<69, "60 - 69",Table1[[#This Row],[Age_Years]]<79, "70 - 79", Table1[[#This Row],[Age_Years]]<89, "80 - 89", TRUE, "90+")} -> 50 - 59 | E11: Female | F11: South South | G11: 28.9 | H11: Former | I11: Low | J11: No | K11: 128 | L11: 78 | M11: 113 | N11: 5.9 | O11: 175 | P11: Drug A | Q11: 69 | R11: 119 | S11: 70 | T11: No | U11: =Table1[[#This Row],[Baseline_SBP]]-Table1[[#This Row],[Week12_SBP]] -> 9 | V11: 69 | W11: 54 | X11: 28.9 | Y11: 113 | Z11: =IF(P11="Drug A", 1,0) -> 1 | AA11: =IF(P11="Drug B", 1,0) -> 0 | AB11: =IF(H11="Current",1,0) -> 0 | AC11: =IF(H11="Former",1,0) -> 1 | AD11: =IF(I11="Moderate",1,0) -> 0 | AE11: =IF(I11="High",1,0) -> 0 | AF11: =N11 -> 5.9
A12: P1010 | B12: 45888 | C12: 48 | D12: {=_xlfn.IFS(Table1[[#This Row],[Age_Years]]<29, "20 - 29", Table1[[#This Row],[Age_Years]]<39, "30 - 39", Table1[[#This Row],[Age_Years]] <49, "40 - 49", Table1[[#This Row],[Age_Years]]<59, "50 - 59",Table1[[#This Row],[Age_Years]]<69, "60 - 69",Table1[[#This Row],[Age_Years]]<79, "70 - 79", Table1[[#This Row],[Age_Years]]<89, "80 - 89", TRUE, "90+")} -> 40 - 49 | E12: Female | F12: South East | G12: 29 | H12: Former | I12: Moderate | J12: No | K12: 123 | L12: 76 | M12: 111 | N12: 5 | O12: 195 | P12: Placebo | Q12: 93 | R12: 122 | S12: 78 | T12: No | U12: =Table1[[#This Row],[Baseline_SBP]]-Table1[[#This Row],[Week12_SBP]] -> 1 | V12: 93 | W12: 48 | X12: 29 | Y12: 111 | Z12: =IF(P12="Drug A", 1,0) -> 0 | AA12: =IF(P12="Drug B", 1,0) -> 0 | AB12: =IF(H12="Current",1,0) -> 0 | AC12: =IF(H12="Former",1,0) -> 1 | AD12: =IF(I12="Moderate",1,0) -> 1 | AE12: =IF(I12="High",1,0) -> 0 | AF12: =N12 -> 5
A13: P1011 | B13: 45757 | C13: 52 | D13: {=_xlfn.IFS(Table1[[#This Row],[Age_Years]]<29, "20 - 29", Table1[[#This Row],[Age_Years]]<39, "30 - 39", Table1[[#This Row],[Age_Years]] <49, "40 - 49", Table1[[#This Row],[Age_Years]]<59, "50 - 59",Table1[[#This Row],[Age_Years]]<69, "60 - 69",Table1[[#This Row],[Age_Years]]<79, "70 - 79", Table1[[#This Row],[Age_Years]]<89, "80 - 89", TRUE, "90+")} -> 50 - 59 | E13: Male | F13: North Central | G13: 31.6 | H13: Never | I13: Moderate | J13: No | K13: 143 | L13: 83 | M13: 114 | N13: 5.2 | O13: 223 | P13: Drug B | Q13: 62 | R13: 126 | S13: 70 | T13: No | U13: =Table1[[#This Row],[Baseline_SBP]]-Table1[[#This Row],[Week12_SBP]] -> 17 | V13: 62 | W13: 52 | X13: 31.6 | Y13: 114 | Z13: =IF(P13="Drug A", 1,0) -> 0 | AA13: =IF(P13="Drug B", 1,0) -> 1 | AB13: =IF(H13="Current",1,0) -> 0 | AC13: =IF(H13="Former",1,0) -> 0 | AD13: =IF(I13="Moderate",1,0) -> 1 | AE13: =IF(I13="High",1,0) -> 0 | AF13: =N13 -> 5.2
... A501: P1499 | B501: 45810 | C501: 28 | D501: {=_xlfn.IFS(Table1[[#This Row],[Age_Years]]<29, "20 - 29", Table1[[#This Row],[Age_Years]]<39, "30 - 39", Table1[[#This Row],[Age_Years]] <49, "40 - 49", Table1[[#This Row],[Age_Years]]<59, "50 - 59",Table1[[#This Row],[Age_Years]]<69, "60 - 69",Table1[[#This Row],[Age_Years]]<79, "70 - 79", Table1[[#This Row],[Age_Years]]<89, "80 - 89", TRUE, "90+")} -> 20 - 29 | E501: Female | F501: South East | G501: 21.4 | H501: Never | I501: High | J501: No | K501: 102 | L501: 67 | M501: 137 | N501: 4 | O501: 186 | P501: Drug B | Q501: 100 | R501: 98 | S501: 59 | T501: No | U501: =Table1[[#This Row],[Baseline_SBP]]-Table1[[#This Row],[Week12_SBP]] -> 4 | V501: 100 | W501: 28 | X501: 21.4 | Y501: 137 | Z501: =IF(P501="Drug A", 1,0) -> 0 | AA501: =IF(P501="Drug B", 1,0) -> 1 | AB501: =IF(H501="Current",1,0) -> 0 | AC501: =IF(H501="Former",1,0) -> 0 | AD501: =IF(I501="Moderate",1,0) -> 0 | AE501: =IF(I501="High",1,0) -> 1 | AF501: =N501 -> 4
D502: {=_xlfn.IFS(Table1[[#This Row],[Age_Years]]<29, "20 - 29", Table1[[#This Row],[Age_Years]]<39, "30 - 39", Table1[[#This Row],[Age_Years]] <49, "40 - 49", Table1[[#This Row],[Age_Years]]<59, "50 - 59",Table1[[#This Row],[Age_Years]]<69, "60 - 69",Table1[[#This Row],[Age_Years]]<79, "70 - 79", Table1[[#This Row],[Age_Years]]<89, "80 - 89", TRUE, "90+")} -> 20 - 29 | U502: =Table1[[#This Row],[Baseline_SBP]]-Table1[[#This Row],[Week12_SBP]] -> 0 | Z502: =IF(P502="Drug A", 1,0) -> 0 | AA502: =IF(P502="Drug B", 1,0) -> 0 | AB502: =IF(H502="Current",1,0) -> 0 | AC502: =IF(H502="Former",1,0) -> 0 | AD502: =IF(I502="Moderate",1,0) -> 0 | AE502: =IF(I502="High",1,0) -> 0 | AF502: =N502 -> 0
D503: {=_xlfn.IFS(Table1[[#This Row],[Age_Years]]<29, "20 - 29", Table1[[#This Row],[Age_Years]]<39, "30 - 39", Table1[[#This Row],[Age_Years]] <49, "40 - 49", Table1[[#This Row],[Age_Years]]<59, "50 - 59",Table1[[#This Row],[Age_Years]]<69, "60 - 69",Table1[[#This Row],[Age_Years]]<79, "70 - 79", Table1[[#This Row],[Age_Years]]<89, "80 - 89", TRUE, "90+")} -> 20 - 29 | U503: =Table1[[#This Row],[Baseline_SBP]]-Table1[[#This Row],[Week12_SBP]] -> 0 | Z503: =IF(P503="Drug A", 1,0) -> 0 | AA503: =IF(P503="Drug B", 1,0) -> 0 | AB503: =IF(H503="Current",1,0) -> 0 | AC503: =IF(H503="Former",1,0) -> 0 | AD503: =IF(I503="Moderate",1,0) -> 0 | AE503: =IF(I503="High",1,0) -> 0 | AF503: =N503 -> 0
D504: {=_xlfn.IFS(Table1[[#This Row],[Age_Years]]<29, "20 - 29", Table1[[#This Row],[Age_Years]]<39, "30 - 39", Table1[[#This Row],[Age_Years]] <49, "40 - 49", Table1[[#This Row],[Age_Years]]<59, "50 - 59",Table1[[#This Row],[Age_Years]]<69, "60 - 69",Table1[[#This Row],[Age_Years]]<79, "70 - 79", Table1[[#This Row],[Age_Years]]<89, "80 - 89", TRUE, "90+")} -> 20 - 29 | U504: =Table1[[#This Row],[Baseline_SBP]]-Table1[[#This Row],[Week12_SBP]] -> 0 | Z504: =IF(P504="Drug A", 1,0) -> 0 | AA504: =IF(P504="Drug B", 1,0) -> 0 | AB504: =IF(H504="Current",1,0) -> 0 | AC504: =IF(H504="Former",1,0) -> 0 | AD504: =IF(I504="Moderate",1,0) -> 0 | AE504: =IF(I504="High",1,0) -> 0 | AF504: =N504 -> 0
